{
 "cells": [
  {
   "cell_type": "code",
   "execution_count": 1,
   "metadata": {},
   "outputs": [],
   "source": [
    "from datetime import datetime\n",
    "from typing import Tuple\n",
    "\n",
    "from pydantic import BaseModel, PositiveInt, EmailStr, validator"
   ]
  },
  {
   "cell_type": "code",
   "execution_count": 4,
   "metadata": {},
   "outputs": [
    {
     "name": "stdout",
     "output_type": "stream",
     "text": [
      "datetime.datetime(2024, 2, 13, 3, 4, 5, tzinfo=TzInfo(UTC))\n",
      "(10, 20)\n"
     ]
    }
   ],
   "source": [
    "class Delivery(BaseModel):\n",
    "    timestamp: datetime\n",
    "    dimensions: Tuple[int, int]\n",
    "    \n",
    "m = Delivery(timestamp='2024-02-13T03:04:05Z', dimensions=['10', '20'])\n",
    "print(repr(m.timestamp))\n",
    "print(m.dimensions)"
   ]
  },
  {
   "cell_type": "code",
   "execution_count": 5,
   "metadata": {},
   "outputs": [
    {
     "ename": "ValidationError",
     "evalue": "1 validation error for Delivery\ndimensions.0\n  Input should be a valid integer, unable to parse string as an integer [type=int_parsing, input_value='10.7', input_type=str]\n    For further information visit https://errors.pydantic.dev/2.5/v/int_parsing",
     "output_type": "error",
     "traceback": [
      "\u001b[1;31m---------------------------------------------------------------------------\u001b[0m",
      "\u001b[1;31mValidationError\u001b[0m                           Traceback (most recent call last)",
      "Cell \u001b[1;32mIn[5], line 1\u001b[0m\n\u001b[1;32m----> 1\u001b[0m m \u001b[38;5;241m=\u001b[39m \u001b[43mDelivery\u001b[49m\u001b[43m(\u001b[49m\u001b[43mtimestamp\u001b[49m\u001b[38;5;241;43m=\u001b[39;49m\u001b[38;5;124;43m'\u001b[39;49m\u001b[38;5;124;43m2024-02-13T03:04:05Z\u001b[39;49m\u001b[38;5;124;43m'\u001b[39;49m\u001b[43m,\u001b[49m\u001b[43m \u001b[49m\u001b[43mdimensions\u001b[49m\u001b[38;5;241;43m=\u001b[39;49m\u001b[43m[\u001b[49m\u001b[38;5;124;43m'\u001b[39;49m\u001b[38;5;124;43m10.7\u001b[39;49m\u001b[38;5;124;43m'\u001b[39;49m\u001b[43m,\u001b[49m\u001b[43m \u001b[49m\u001b[38;5;124;43m'\u001b[39;49m\u001b[38;5;124;43m20\u001b[39;49m\u001b[38;5;124;43m'\u001b[39;49m\u001b[43m]\u001b[49m\u001b[43m)\u001b[49m\n\u001b[0;32m      2\u001b[0m \u001b[38;5;28mprint\u001b[39m(\u001b[38;5;28mrepr\u001b[39m(m\u001b[38;5;241m.\u001b[39mtimestamp))\n\u001b[0;32m      3\u001b[0m \u001b[38;5;28mprint\u001b[39m(m\u001b[38;5;241m.\u001b[39mdimensions)\n",
      "File \u001b[1;32mc:\\Users\\Admin\\AppData\\Local\\Programs\\Python\\Python312\\Lib\\site-packages\\pydantic\\main.py:164\u001b[0m, in \u001b[0;36mBaseModel.__init__\u001b[1;34m(__pydantic_self__, **data)\u001b[0m\n\u001b[0;32m    162\u001b[0m \u001b[38;5;66;03m# `__tracebackhide__` tells pytest and some other tools to omit this function from tracebacks\u001b[39;00m\n\u001b[0;32m    163\u001b[0m __tracebackhide__ \u001b[38;5;241m=\u001b[39m \u001b[38;5;28;01mTrue\u001b[39;00m\n\u001b[1;32m--> 164\u001b[0m \u001b[43m__pydantic_self__\u001b[49m\u001b[38;5;241;43m.\u001b[39;49m\u001b[43m__pydantic_validator__\u001b[49m\u001b[38;5;241;43m.\u001b[39;49m\u001b[43mvalidate_python\u001b[49m\u001b[43m(\u001b[49m\u001b[43mdata\u001b[49m\u001b[43m,\u001b[49m\u001b[43m \u001b[49m\u001b[43mself_instance\u001b[49m\u001b[38;5;241;43m=\u001b[39;49m\u001b[43m__pydantic_self__\u001b[49m\u001b[43m)\u001b[49m\n",
      "\u001b[1;31mValidationError\u001b[0m: 1 validation error for Delivery\ndimensions.0\n  Input should be a valid integer, unable to parse string as an integer [type=int_parsing, input_value='10.7', input_type=str]\n    For further information visit https://errors.pydantic.dev/2.5/v/int_parsing"
     ]
    }
   ],
   "source": [
    "    \n",
    "m = Delivery(timestamp='2024-02-13T03:04:05Z', dimensions=['10.7', '20'])\n",
    "print(repr(m.timestamp))\n",
    "print(m.dimensions)"
   ]
  },
  {
   "cell_type": "code",
   "execution_count": 10,
   "metadata": {},
   "outputs": [
    {
     "name": "stdout",
     "output_type": "stream",
     "text": [
      "123\n"
     ]
    },
    {
     "data": {
      "text/plain": [
       "{'id': 123,\n",
       " 'name': 'John Doe',\n",
       " 'signup_ts': datetime.datetime(2019, 6, 1, 12, 22),\n",
       " 'tastes': {'wine': 9, 'cheese': 7, 'cabbage': 1}}"
      ]
     },
     "metadata": {},
     "output_type": "display_data"
    }
   ],
   "source": [
    "from datetime import datetime\n",
    "\n",
    "from pydantic import BaseModel, PositiveInt\n",
    "\n",
    "\n",
    "class User(BaseModel):\n",
    "    id: int  \n",
    "    name: str = 'John Doe'  \n",
    "    signup_ts: datetime | None  \n",
    "    tastes: dict[str, PositiveInt]  \n",
    "\n",
    "\n",
    "external_data = {\n",
    "    'id': 123,\n",
    "    'signup_ts': '2019-06-01 12:22',  \n",
    "    'tastes': {\n",
    "        'wine': 9,\n",
    "        b'cheese': 7,  \n",
    "        'cabbage': '1',  \n",
    "    },\n",
    "}\n",
    "\n",
    "user = User(**external_data)  \n",
    "\n",
    "print(user.id)  \n",
    "\n",
    "display(user.model_dump())  \n"
   ]
  },
  {
   "cell_type": "code",
   "execution_count": 12,
   "metadata": {},
   "outputs": [
    {
     "data": {
      "text/plain": [
       "[{'type': 'int_parsing',\n",
       "  'loc': ('id',),\n",
       "  'msg': 'Input should be a valid integer, unable to parse string as an integer',\n",
       "  'input': 'not an int',\n",
       "  'url': 'https://errors.pydantic.dev/2.5/v/int_parsing'},\n",
       " {'type': 'missing',\n",
       "  'loc': ('signup_ts',),\n",
       "  'msg': 'Field required',\n",
       "  'input': {'id': 'not an int', 'tastes': {}},\n",
       "  'url': 'https://errors.pydantic.dev/2.5/v/missing'}]"
      ]
     },
     "metadata": {},
     "output_type": "display_data"
    }
   ],
   "source": [
    "# continuing the above example...\n",
    "\n",
    "from pydantic import ValidationError\n",
    "\n",
    "\n",
    "class User(BaseModel):\n",
    "    id: int\n",
    "    name: str = 'John Doe'\n",
    "    signup_ts: datetime | None\n",
    "    tastes: dict[str, PositiveInt]\n",
    "\n",
    "\n",
    "external_data = {'id': 'not an int', 'tastes': {}}  \n",
    "\n",
    "try:\n",
    "    User(**external_data)  \n",
    "except ValidationError as e:\n",
    "    display(e.errors())\n",
    "\n"
   ]
  },
  {
   "cell_type": "code",
   "execution_count": 13,
   "metadata": {},
   "outputs": [
    {
     "ename": "ValidationError",
     "evalue": "2 validation errors for User\nid\n  Input should be a valid integer, unable to parse string as an integer [type=int_parsing, input_value='not an int', input_type=str]\n    For further information visit https://errors.pydantic.dev/2.5/v/int_parsing\nsignup_ts\n  Field required [type=missing, input_value={'id': 'not an int', 'tastes': {}}, input_type=dict]\n    For further information visit https://errors.pydantic.dev/2.5/v/missing",
     "output_type": "error",
     "traceback": [
      "\u001b[1;31m---------------------------------------------------------------------------\u001b[0m",
      "\u001b[1;31mValidationError\u001b[0m                           Traceback (most recent call last)",
      "Cell \u001b[1;32mIn[13], line 1\u001b[0m\n\u001b[1;32m----> 1\u001b[0m \u001b[43mUser\u001b[49m\u001b[43m(\u001b[49m\u001b[38;5;241;43m*\u001b[39;49m\u001b[38;5;241;43m*\u001b[39;49m\u001b[43mexternal_data\u001b[49m\u001b[43m)\u001b[49m  \n",
      "File \u001b[1;32mc:\\Users\\Admin\\AppData\\Local\\Programs\\Python\\Python312\\Lib\\site-packages\\pydantic\\main.py:164\u001b[0m, in \u001b[0;36mBaseModel.__init__\u001b[1;34m(__pydantic_self__, **data)\u001b[0m\n\u001b[0;32m    162\u001b[0m \u001b[38;5;66;03m# `__tracebackhide__` tells pytest and some other tools to omit this function from tracebacks\u001b[39;00m\n\u001b[0;32m    163\u001b[0m __tracebackhide__ \u001b[38;5;241m=\u001b[39m \u001b[38;5;28;01mTrue\u001b[39;00m\n\u001b[1;32m--> 164\u001b[0m \u001b[43m__pydantic_self__\u001b[49m\u001b[38;5;241;43m.\u001b[39;49m\u001b[43m__pydantic_validator__\u001b[49m\u001b[38;5;241;43m.\u001b[39;49m\u001b[43mvalidate_python\u001b[49m\u001b[43m(\u001b[49m\u001b[43mdata\u001b[49m\u001b[43m,\u001b[49m\u001b[43m \u001b[49m\u001b[43mself_instance\u001b[49m\u001b[38;5;241;43m=\u001b[39;49m\u001b[43m__pydantic_self__\u001b[49m\u001b[43m)\u001b[49m\n",
      "\u001b[1;31mValidationError\u001b[0m: 2 validation errors for User\nid\n  Input should be a valid integer, unable to parse string as an integer [type=int_parsing, input_value='not an int', input_type=str]\n    For further information visit https://errors.pydantic.dev/2.5/v/int_parsing\nsignup_ts\n  Field required [type=missing, input_value={'id': 'not an int', 'tastes': {}}, input_type=dict]\n    For further information visit https://errors.pydantic.dev/2.5/v/missing"
     ]
    }
   ],
   "source": [
    "User(**external_data)  "
   ]
  },
  {
   "cell_type": "markdown",
   "metadata": {},
   "source": [
    "# Model\n"
   ]
  },
  {
   "cell_type": "code",
   "execution_count": 5,
   "metadata": {},
   "outputs": [
    {
     "name": "stderr",
     "output_type": "stream",
     "text": [
      "C:\\Users\\Admin\\AppData\\Local\\Temp\\ipykernel_10260\\1346193448.py:6: PydanticDeprecatedSince20: Pydantic V1 style `@validator` validators are deprecated. You should migrate to Pydantic V2 style `@field_validator` validators, see the migration guide for more details. Deprecated in Pydantic V2.0 to be removed in V3.0. See Pydantic V2 Migration Guide at https://errors.pydantic.dev/2.5/migration/\n",
      "  @validator('account_id')\n"
     ]
    },
    {
     "data": {
      "text/plain": [
       "'{\"name\":\"Zia Khan\",\"email\":\"zia@panaloud.com\",\"account_id\":100}'"
      ]
     },
     "metadata": {},
     "output_type": "display_data"
    },
    {
     "data": {
      "text/plain": [
       "User(name='Zia Khan', email='zia@panaloud.com', account_id=100)"
      ]
     },
     "metadata": {},
     "output_type": "display_data"
    }
   ],
   "source": [
    "class User(BaseModel):\n",
    "    name: str\n",
    "    email: EmailStr\n",
    "    account_id: int\n",
    "    \n",
    "    @validator('account_id')\n",
    "    def validate_account_id(cls, value: int):\n",
    "        \n",
    "        if value <=0:\n",
    "            raise ValueError(f\"Account ID must be positive: {value}\")\n",
    "        return value\n",
    "    \n",
    "user1: User = User(name='Zia Khan', email='zia@panaloud.com', account_id=100)\n",
    "\n",
    "user_json_str: str = user1.model_dump_json()\n",
    "display(user_json_str)\n",
    "\n",
    "user_obj: User = User.model_validate_json(user_json_str)\n",
    "display(user_obj)"
   ]
  },
  {
   "cell_type": "code",
   "execution_count": 6,
   "metadata": {},
   "outputs": [
    {
     "name": "stderr",
     "output_type": "stream",
     "text": [
      "C:\\Users\\Admin\\AppData\\Local\\Temp\\ipykernel_10260\\1966843519.py:6: PydanticDeprecatedSince20: Pydantic V1 style `@validator` validators are deprecated. You should migrate to Pydantic V2 style `@field_validator` validators, see the migration guide for more details. Deprecated in Pydantic V2.0 to be removed in V3.0. See Pydantic V2 Migration Guide at https://errors.pydantic.dev/2.5/migration/\n",
      "  @validator('account_id')\n"
     ]
    },
    {
     "ename": "ValidationError",
     "evalue": "1 validation error for User\nemail\n  value is not a valid email address: The email address is not valid. It must have exactly one @-sign. [type=value_error, input_value='ziapanaloud.com', input_type=str]",
     "output_type": "error",
     "traceback": [
      "\u001b[1;31m---------------------------------------------------------------------------\u001b[0m",
      "\u001b[1;31mValidationError\u001b[0m                           Traceback (most recent call last)",
      "Cell \u001b[1;32mIn[6], line 13\u001b[0m\n\u001b[0;32m     10\u001b[0m             \u001b[38;5;28;01mraise\u001b[39;00m \u001b[38;5;167;01mValueError\u001b[39;00m(\u001b[38;5;124mf\u001b[39m\u001b[38;5;124m\"\u001b[39m\u001b[38;5;124mAccount ID must be positive: \u001b[39m\u001b[38;5;132;01m{\u001b[39;00mvalue\u001b[38;5;132;01m}\u001b[39;00m\u001b[38;5;124m\"\u001b[39m)\n\u001b[0;32m     11\u001b[0m         \u001b[38;5;28;01mreturn\u001b[39;00m value\n\u001b[1;32m---> 13\u001b[0m user1: User \u001b[38;5;241m=\u001b[39m \u001b[43mUser\u001b[49m\u001b[43m(\u001b[49m\u001b[43mname\u001b[49m\u001b[38;5;241;43m=\u001b[39;49m\u001b[38;5;124;43m'\u001b[39;49m\u001b[38;5;124;43mZia Khan\u001b[39;49m\u001b[38;5;124;43m'\u001b[39;49m\u001b[43m,\u001b[49m\u001b[43m \u001b[49m\u001b[43memail\u001b[49m\u001b[38;5;241;43m=\u001b[39;49m\u001b[38;5;124;43m'\u001b[39;49m\u001b[38;5;124;43mziapanaloud.com\u001b[39;49m\u001b[38;5;124;43m'\u001b[39;49m\u001b[43m,\u001b[49m\u001b[43m \u001b[49m\u001b[43maccount_id\u001b[49m\u001b[38;5;241;43m=\u001b[39;49m\u001b[38;5;241;43m100\u001b[39;49m\u001b[43m)\u001b[49m\n\u001b[0;32m     15\u001b[0m user_json_str: \u001b[38;5;28mstr\u001b[39m \u001b[38;5;241m=\u001b[39m user1\u001b[38;5;241m.\u001b[39mmodel_dump_json()\n\u001b[0;32m     16\u001b[0m display(user_json_str)\n",
      "File \u001b[1;32mc:\\Users\\Admin\\AppData\\Local\\Programs\\Python\\Python312\\Lib\\site-packages\\pydantic\\main.py:164\u001b[0m, in \u001b[0;36mBaseModel.__init__\u001b[1;34m(__pydantic_self__, **data)\u001b[0m\n\u001b[0;32m    162\u001b[0m \u001b[38;5;66;03m# `__tracebackhide__` tells pytest and some other tools to omit this function from tracebacks\u001b[39;00m\n\u001b[0;32m    163\u001b[0m __tracebackhide__ \u001b[38;5;241m=\u001b[39m \u001b[38;5;28;01mTrue\u001b[39;00m\n\u001b[1;32m--> 164\u001b[0m \u001b[43m__pydantic_self__\u001b[49m\u001b[38;5;241;43m.\u001b[39;49m\u001b[43m__pydantic_validator__\u001b[49m\u001b[38;5;241;43m.\u001b[39;49m\u001b[43mvalidate_python\u001b[49m\u001b[43m(\u001b[49m\u001b[43mdata\u001b[49m\u001b[43m,\u001b[49m\u001b[43m \u001b[49m\u001b[43mself_instance\u001b[49m\u001b[38;5;241;43m=\u001b[39;49m\u001b[43m__pydantic_self__\u001b[49m\u001b[43m)\u001b[49m\n",
      "\u001b[1;31mValidationError\u001b[0m: 1 validation error for User\nemail\n  value is not a valid email address: The email address is not valid. It must have exactly one @-sign. [type=value_error, input_value='ziapanaloud.com', input_type=str]"
     ]
    }
   ],
   "source": [
    "class User(BaseModel):\n",
    "    name: str\n",
    "    email: EmailStr\n",
    "    account_id: int\n",
    "    \n",
    "    @validator('account_id')\n",
    "    def validate_account_id(cls, value: int):\n",
    "        \n",
    "        if value <=0:\n",
    "            raise ValueError(f\"Account ID must be positive: {value}\")\n",
    "        return value\n",
    "    \n",
    "user1: User = User(name='Zia Khan', email='ziapanaloud.com', account_id=100)\n",
    "\n",
    "user_json_str: str = user1.model_dump_json()\n",
    "display(user_json_str)\n",
    "\n",
    "user_obj: User = User.model_validate_json(user_json_str)\n",
    "display(user_obj)"
   ]
  },
  {
   "cell_type": "code",
   "execution_count": 8,
   "metadata": {},
   "outputs": [
    {
     "name": "stderr",
     "output_type": "stream",
     "text": [
      "C:\\Users\\Admin\\AppData\\Local\\Temp\\ipykernel_10260\\1186075093.py:6: PydanticDeprecatedSince20: Pydantic V1 style `@validator` validators are deprecated. You should migrate to Pydantic V2 style `@field_validator` validators, see the migration guide for more details. Deprecated in Pydantic V2.0 to be removed in V3.0. See Pydantic V2 Migration Guide at https://errors.pydantic.dev/2.5/migration/\n",
      "  @validator('account_id')\n"
     ]
    },
    {
     "ename": "ValidationError",
     "evalue": "2 validation errors for User\nemail\n  value is not a valid email address: The email address is not valid. It must have exactly one @-sign. [type=value_error, input_value='ziapanaloud.com', input_type=str]\naccount_id\n  Value error, Account ID must be positive: -100 [type=value_error, input_value=-100, input_type=int]\n    For further information visit https://errors.pydantic.dev/2.5/v/value_error",
     "output_type": "error",
     "traceback": [
      "\u001b[1;31m---------------------------------------------------------------------------\u001b[0m",
      "\u001b[1;31mValidationError\u001b[0m                           Traceback (most recent call last)",
      "Cell \u001b[1;32mIn[8], line 13\u001b[0m\n\u001b[0;32m     10\u001b[0m             \u001b[38;5;28;01mraise\u001b[39;00m \u001b[38;5;167;01mValueError\u001b[39;00m(\u001b[38;5;124mf\u001b[39m\u001b[38;5;124m\"\u001b[39m\u001b[38;5;124mAccount ID must be positive: \u001b[39m\u001b[38;5;132;01m{\u001b[39;00mvalue\u001b[38;5;132;01m}\u001b[39;00m\u001b[38;5;124m\"\u001b[39m)\n\u001b[0;32m     11\u001b[0m         \u001b[38;5;28;01mreturn\u001b[39;00m value\n\u001b[1;32m---> 13\u001b[0m user1: User \u001b[38;5;241m=\u001b[39m \u001b[43mUser\u001b[49m\u001b[43m(\u001b[49m\u001b[43mname\u001b[49m\u001b[38;5;241;43m=\u001b[39;49m\u001b[38;5;124;43m'\u001b[39;49m\u001b[38;5;124;43mZia Khan\u001b[39;49m\u001b[38;5;124;43m'\u001b[39;49m\u001b[43m,\u001b[49m\u001b[43m \u001b[49m\u001b[43memail\u001b[49m\u001b[38;5;241;43m=\u001b[39;49m\u001b[38;5;124;43m'\u001b[39;49m\u001b[38;5;124;43mziapanaloud.com\u001b[39;49m\u001b[38;5;124;43m'\u001b[39;49m\u001b[43m,\u001b[49m\u001b[43m \u001b[49m\u001b[43maccount_id\u001b[49m\u001b[38;5;241;43m=\u001b[39;49m\u001b[38;5;241;43m-\u001b[39;49m\u001b[38;5;241;43m100\u001b[39;49m\u001b[43m)\u001b[49m\n\u001b[0;32m     15\u001b[0m user_json_str: \u001b[38;5;28mstr\u001b[39m \u001b[38;5;241m=\u001b[39m user1\u001b[38;5;241m.\u001b[39mmodel_dump_json()\n\u001b[0;32m     16\u001b[0m display(user_json_str)\n",
      "File \u001b[1;32mc:\\Users\\Admin\\AppData\\Local\\Programs\\Python\\Python312\\Lib\\site-packages\\pydantic\\main.py:164\u001b[0m, in \u001b[0;36mBaseModel.__init__\u001b[1;34m(__pydantic_self__, **data)\u001b[0m\n\u001b[0;32m    162\u001b[0m \u001b[38;5;66;03m# `__tracebackhide__` tells pytest and some other tools to omit this function from tracebacks\u001b[39;00m\n\u001b[0;32m    163\u001b[0m __tracebackhide__ \u001b[38;5;241m=\u001b[39m \u001b[38;5;28;01mTrue\u001b[39;00m\n\u001b[1;32m--> 164\u001b[0m \u001b[43m__pydantic_self__\u001b[49m\u001b[38;5;241;43m.\u001b[39;49m\u001b[43m__pydantic_validator__\u001b[49m\u001b[38;5;241;43m.\u001b[39;49m\u001b[43mvalidate_python\u001b[49m\u001b[43m(\u001b[49m\u001b[43mdata\u001b[49m\u001b[43m,\u001b[49m\u001b[43m \u001b[49m\u001b[43mself_instance\u001b[49m\u001b[38;5;241;43m=\u001b[39;49m\u001b[43m__pydantic_self__\u001b[49m\u001b[43m)\u001b[49m\n",
      "\u001b[1;31mValidationError\u001b[0m: 2 validation errors for User\nemail\n  value is not a valid email address: The email address is not valid. It must have exactly one @-sign. [type=value_error, input_value='ziapanaloud.com', input_type=str]\naccount_id\n  Value error, Account ID must be positive: -100 [type=value_error, input_value=-100, input_type=int]\n    For further information visit https://errors.pydantic.dev/2.5/v/value_error"
     ]
    }
   ],
   "source": [
    "class User(BaseModel):\n",
    "    name: str\n",
    "    email: EmailStr\n",
    "    account_id: int\n",
    "    \n",
    "    @validator('account_id')\n",
    "    def validate_account_id(cls, value: int):\n",
    "        \n",
    "        if value <=0:\n",
    "            raise ValueError(f\"Account ID must be positive: {value}\")\n",
    "        return value\n",
    "    \n",
    "user1: User = User(name='Zia Khan', email='ziapanaloud.com', account_id=-100)\n",
    "\n",
    "user_json_str: str = user1.model_dump_json()\n",
    "display(user_json_str)\n",
    "\n",
    "user_obj: User = User.model_validate_json(user_json_str)\n",
    "display(user_obj)"
   ]
  },
  {
   "cell_type": "code",
   "execution_count": null,
   "metadata": {},
   "outputs": [],
   "source": []
  }
 ],
 "metadata": {
  "kernelspec": {
   "display_name": "Python 3",
   "language": "python",
   "name": "python3"
  },
  "language_info": {
   "codemirror_mode": {
    "name": "ipython",
    "version": 3
   },
   "file_extension": ".py",
   "mimetype": "text/x-python",
   "name": "python",
   "nbconvert_exporter": "python",
   "pygments_lexer": "ipython3",
   "version": "3.12.0"
  }
 },
 "nbformat": 4,
 "nbformat_minor": 2
}
